 2019-11-05 16:31:17,450 - ERROR - views.py - all_data - 44 - http://127.0.0.1:5000/all
NoneType: None
2019-11-05 16:31:45,297 - ERROR - views.py - all_data - 44 - http://127.0.0.1:5000/all
NoneType: None
2019-11-05 16:32:14,198 - ERROR - views.py - all_data - 44 - http://127.0.0.1:5000/all
NoneType: None
2019-11-05 16:33:54,084 - INFO - views.py - all_data - 44 - /all?
2019-11-05 16:34:15,936 - INFO - views.py - all_data - 44 - http://127.0.0.1:5000/all
2019-11-05 16:42:59,419 - INFO - views.py - all_data - 44 - http://127.0.0.1:5000/all
2019-11-05 16:43:05,387 - INFO - views.py - all_data - 44 - http://127.0.0.1:5000/all
2019-11-05 16:43:05,900 - INFO - views.py - all_data - 44 - http://127.0.0.1:5000/all
2019-11-05 16:43:05,949 - INFO - views.py - all_data - 44 - http://127.0.0.1:5000/all
2019-11-05 16:43:05,963 - INFO - views.py - all_data - 44 - http://127.0.0.1:5000/all
2019-11-05 16:43:06,004 - INFO - views.py - all_data - 44 - http://127.0.0.1:5000/all
2019-11-05 16:43:06,025 - INFO - views.py - all_data - 44 - http://127.0.0.1:5000/all
2019-11-05 16:43:06,074 - INFO - views.py - all_data - 44 - http://127.0.0.1:5000/all
2019-11-05 16:43:06,090 - INFO - views.py - all_data - 44 - http://127.0.0.1:5000/all
2019-11-05 16:43:06,140 - INFO - views.py - all_data - 44 - http://127.0.0.1:5000/all
2019-11-05 16:43:06,156 - INFO - views.py - all_data - 44 - http://127.0.0.1:5000/all
2019-11-05 16:43:06,206 - INFO - views.py - all_data - 44 - http://127.0.0.1:5000/all
2019-11-05 16:43:06,223 - INFO - views.py - all_data - 44 - http://127.0.0.1:5000/all
2019-11-05 16:43:06,272 - INFO - views.py - all_data - 44 - http://127.0.0.1:5000/all
2019-11-05 16:43:06,295 - INFO - views.py - all_data - 44 - http://127.0.0.1:5000/all
2019-11-05 16:43:06,338 - INFO - views.py - all_data - 44 - http://127.0.0.1:5000/all
2019-11-05 16:43:06,355 - INFO - views.py - all_data - 44 - http://127.0.0.1:5000/all
2019-11-05 16:43:06,406 - INFO - views.py - all_data - 44 - http://127.0.0.1:5000/all
2019-11-05 16:43:06,425 - INFO - views.py - all_data - 44 - http://127.0.0.1:5000/all
2019-11-05 16:43:06,469 - INFO - views.py - all_data - 44 - http://127.0.0.1:5000/all
2019-11-05 16:43:06,501 - INFO - views.py - all_data - 44 - http://127.0.0.1:5000/all
2019-11-05 16:43:06,535 - INFO - views.py - all_data - 44 - http://127.0.0.1:5000/all
2019-11-05 16:43:06,565 - INFO - views.py - all_data - 44 - http://127.0.0.1:5000/all
2019-11-05 16:43:06,600 - INFO - views.py - all_data - 44 - http://127.0.0.1:5000/all
2019-11-05 17:35:03,252 - INFO - views.py - all_data - 44 - http://127.0.0.1:5000/all
2019-11-05 17:35:34,151 - INFO - views.py - all_data - 44 - http://127.0.0.1:5000/all
2019-11-05 17:51:34,276 - INFO - views.py - all_data - 44 - http://127.0.0.1:5000/all
2019-11-05 17:51:36,663 - INFO - views.py - all_data - 44 - http://127.0.0.1:5000/all
2019-11-05 17:52:23,555 - INFO - views.py - all_data - 44 - http://127.0.0.1:5000/all
2019-11-05 17:52:33,878 - INFO - views.py - all_data - 44 - http://127.0.0.1:5000/all
2019-11-05 17:54:01,517 - INFO - views.py - all_data - 44 - http://127.0.0.1:5000/all
2019-11-05 17:54:05,137 - INFO - views.py - all_data - 44 - http://127.0.0.1:5000/all
2019-11-05 18:01:44,665 - INFO - views.py - all_data - 44 - http://127.0.0.1:5000/all
2019-11-06 10:27:13,899 - INFO - views.py - all_data - 44 - http://127.0.0.1:5000/all
2019-11-06 10:51:10,992 - ERROR - app.py - log_exception - 1891 - Exception on /login [GET]
Traceback (most recent call last):
  File "C:\Users\oerbin\pyvt\flask\lib\site-packages\flask\app.py", line 2446, in wsgi_app
    response = self.full_dispatch_request()
  File "C:\Users\oerbin\pyvt\flask\lib\site-packages\flask\app.py", line 1951, in full_dispatch_request
    rv = self.handle_user_exception(e)
  File "C:\Users\oerbin\pyvt\flask\lib\site-packages\flask\app.py", line 1820, in handle_user_exception
    reraise(exc_type, exc_value, tb)
  File "C:\Users\oerbin\pyvt\flask\lib\site-packages\flask\_compat.py", line 39, in reraise
    raise value
  File "C:\Users\oerbin\pyvt\flask\lib\site-packages\flask\app.py", line 1949, in full_dispatch_request
    rv = self.dispatch_request()
  File "C:\Users\oerbin\pyvt\flask\lib\site-packages\flask\app.py", line 1935, in dispatch_request
    return self.view_functions[rule.endpoint](**req.view_args)
  File "c:\Users\oerbin\python-code\monitor\main\views.py", line 32, in login
    if session['username']:
  File "C:\Users\oerbin\pyvt\flask\lib\site-packages\werkzeug\local.py", line 378, in <lambda>
    __getitem__ = lambda x, i: x._get_current_object()[i]
  File "C:\Users\oerbin\pyvt\flask\lib\site-packages\flask\sessions.py", line 84, in __getitem__
    return super(SecureCookieSession, self).__getitem__(key)
KeyError: 'username'
2019-11-06 10:51:15,904 - ERROR - app.py - log_exception - 1891 - Exception on /login [GET]
Traceback (most recent call last):
  File "C:\Users\oerbin\pyvt\flask\lib\site-packages\flask\app.py", line 2446, in wsgi_app
    response = self.full_dispatch_request()
  File "C:\Users\oerbin\pyvt\flask\lib\site-packages\flask\app.py", line 1951, in full_dispatch_request
    rv = self.handle_user_exception(e)
  File "C:\Users\oerbin\pyvt\flask\lib\site-packages\flask\app.py", line 1820, in handle_user_exception
    reraise(exc_type, exc_value, tb)
  File "C:\Users\oerbin\pyvt\flask\lib\site-packages\flask\_compat.py", line 39, in reraise
    raise value
  File "C:\Users\oerbin\pyvt\flask\lib\site-packages\flask\app.py", line 1949, in full_dispatch_request
    rv = self.dispatch_request()
  File "C:\Users\oerbin\pyvt\flask\lib\site-packages\flask\app.py", line 1935, in dispatch_request
    return self.view_functions[rule.endpoint](**req.view_args)
  File "c:\Users\oerbin\python-code\monitor\main\views.py", line 32, in login
    if session['username']:
  File "C:\Users\oerbin\pyvt\flask\lib\site-packages\werkzeug\local.py", line 378, in <lambda>
    __getitem__ = lambda x, i: x._get_current_object()[i]
  File "C:\Users\oerbin\pyvt\flask\lib\site-packages\flask\sessions.py", line 84, in __getitem__
    return super(SecureCookieSession, self).__getitem__(key)
KeyError: 'username'
2019-11-06 10:52:03,614 - ERROR - app.py - log_exception - 1891 - Exception on /login [GET]
Traceback (most recent call last):
  File "C:\Users\oerbin\pyvt\flask\lib\site-packages\flask\app.py", line 2446, in wsgi_app
    response = self.full_dispatch_request()
  File "C:\Users\oerbin\pyvt\flask\lib\site-packages\flask\app.py", line 1951, in full_dispatch_request
    rv = self.handle_user_exception(e)
  File "C:\Users\oerbin\pyvt\flask\lib\site-packages\flask\app.py", line 1820, in handle_user_exception
    reraise(exc_type, exc_value, tb)
  File "C:\Users\oerbin\pyvt\flask\lib\site-packages\flask\_compat.py", line 39, in reraise
    raise value
  File "C:\Users\oerbin\pyvt\flask\lib\site-packages\flask\app.py", line 1949, in full_dispatch_request
    rv = self.dispatch_request()
  File "C:\Users\oerbin\pyvt\flask\lib\site-packages\flask\app.py", line 1935, in dispatch_request
    return self.view_functions[rule.endpoint](**req.view_args)
  File "c:\Users\oerbin\python-code\monitor\main\views.py", line 32, in login
    if session['username']:
  File "C:\Users\oerbin\pyvt\flask\lib\site-packages\werkzeug\local.py", line 378, in <lambda>
    __getitem__ = lambda x, i: x._get_current_object()[i]
  File "C:\Users\oerbin\pyvt\flask\lib\site-packages\flask\sessions.py", line 84, in __getitem__
    return super(SecureCookieSession, self).__getitem__(key)
KeyError: 'username'
2019-11-06 10:52:04,151 - ERROR - app.py - log_exception - 1891 - Exception on /login [GET]
Traceback (most recent call last):
  File "C:\Users\oerbin\pyvt\flask\lib\site-packages\flask\app.py", line 2446, in wsgi_app
    response = self.full_dispatch_request()
  File "C:\Users\oerbin\pyvt\flask\lib\site-packages\flask\app.py", line 1951, in full_dispatch_request
    rv = self.handle_user_exception(e)
  File "C:\Users\oerbin\pyvt\flask\lib\site-packages\flask\app.py", line 1820, in handle_user_exception
    reraise(exc_type, exc_value, tb)
  File "C:\Users\oerbin\pyvt\flask\lib\site-packages\flask\_compat.py", line 39, in reraise
    raise value
  File "C:\Users\oerbin\pyvt\flask\lib\site-packages\flask\app.py", line 1949, in full_dispatch_request
    rv = self.dispatch_request()
  File "C:\Users\oerbin\pyvt\flask\lib\site-packages\flask\app.py", line 1935, in dispatch_request
    return self.view_functions[rule.endpoint](**req.view_args)
  File "c:\Users\oerbin\python-code\monitor\main\views.py", line 32, in login
    if session['username']:
  File "C:\Users\oerbin\pyvt\flask\lib\site-packages\werkzeug\local.py", line 378, in <lambda>
    __getitem__ = lambda x, i: x._get_current_object()[i]
  File "C:\Users\oerbin\pyvt\flask\lib\site-packages\flask\sessions.py", line 84, in __getitem__
    return super(SecureCookieSession, self).__getitem__(key)
KeyError: 'username'
2019-11-06 10:52:04,333 - ERROR - app.py - log_exception - 1891 - Exception on /login [GET]
Traceback (most recent call last):
  File "C:\Users\oerbin\pyvt\flask\lib\site-packages\flask\app.py", line 2446, in wsgi_app
    response = self.full_dispatch_request()
  File "C:\Users\oerbin\pyvt\flask\lib\site-packages\flask\app.py", line 1951, in full_dispatch_request
    rv = self.handle_user_exception(e)
  File "C:\Users\oerbin\pyvt\flask\lib\site-packages\flask\app.py", line 1820, in handle_user_exception
    reraise(exc_type, exc_value, tb)
  File "C:\Users\oerbin\pyvt\flask\lib\site-packages\flask\_compat.py", line 39, in reraise
    raise value
  File "C:\Users\oerbin\pyvt\flask\lib\site-packages\flask\app.py", line 1949, in full_dispatch_request
    rv = self.dispatch_request()
  File "C:\Users\oerbin\pyvt\flask\lib\site-packages\flask\app.py", line 1935, in dispatch_request
    return self.view_functions[rule.endpoint](**req.view_args)
  File "c:\Users\oerbin\python-code\monitor\main\views.py", line 32, in login
    if session['username']:
  File "C:\Users\oerbin\pyvt\flask\lib\site-packages\werkzeug\local.py", line 378, in <lambda>
    __getitem__ = lambda x, i: x._get_current_object()[i]
  File "C:\Users\oerbin\pyvt\flask\lib\site-packages\flask\sessions.py", line 84, in __getitem__
    return super(SecureCookieSession, self).__getitem__(key)
KeyError: 'username'
2019-11-06 10:52:04,512 - ERROR - app.py - log_exception - 1891 - Exception on /login [GET]
Traceback (most recent call last):
  File "C:\Users\oerbin\pyvt\flask\lib\site-packages\flask\app.py", line 2446, in wsgi_app
    response = self.full_dispatch_request()
  File "C:\Users\oerbin\pyvt\flask\lib\site-packages\flask\app.py", line 1951, in full_dispatch_request
    rv = self.handle_user_exception(e)
  File "C:\Users\oerbin\pyvt\flask\lib\site-packages\flask\app.py", line 1820, in handle_user_exception
    reraise(exc_type, exc_value, tb)
  File "C:\Users\oerbin\pyvt\flask\lib\site-packages\flask\_compat.py", line 39, in reraise
    raise value
  File "C:\Users\oerbin\pyvt\flask\lib\site-packages\flask\app.py", line 1949, in full_dispatch_request
    rv = self.dispatch_request()
  File "C:\Users\oerbin\pyvt\flask\lib\site-packages\flask\app.py", line 1935, in dispatch_request
    return self.view_functions[rule.endpoint](**req.view_args)
  File "c:\Users\oerbin\python-code\monitor\main\views.py", line 32, in login
    if session['username']:
  File "C:\Users\oerbin\pyvt\flask\lib\site-packages\werkzeug\local.py", line 378, in <lambda>
    __getitem__ = lambda x, i: x._get_current_object()[i]
  File "C:\Users\oerbin\pyvt\flask\lib\site-packages\flask\sessions.py", line 84, in __getitem__
    return super(SecureCookieSession, self).__getitem__(key)
KeyError: 'username'
2019-11-06 10:53:03,611 - ERROR - app.py - log_exception - 1891 - Exception on /login [GET]
Traceback (most recent call last):
  File "C:\Users\oerbin\pyvt\flask\lib\site-packages\flask\app.py", line 2446, in wsgi_app
    response = self.full_dispatch_request()
  File "C:\Users\oerbin\pyvt\flask\lib\site-packages\flask\app.py", line 1951, in full_dispatch_request
    rv = self.handle_user_exception(e)
  File "C:\Users\oerbin\pyvt\flask\lib\site-packages\flask\app.py", line 1820, in handle_user_exception
    reraise(exc_type, exc_value, tb)
  File "C:\Users\oerbin\pyvt\flask\lib\site-packages\flask\_compat.py", line 39, in reraise
    raise value
  File "C:\Users\oerbin\pyvt\flask\lib\site-packages\flask\app.py", line 1949, in full_dispatch_request
    rv = self.dispatch_request()
  File "C:\Users\oerbin\pyvt\flask\lib\site-packages\flask\app.py", line 1935, in dispatch_request
    return self.view_functions[rule.endpoint](**req.view_args)
  File "c:\Users\oerbin\python-code\monitor\main\views.py", line 32, in login
    if session['username']:
  File "C:\Users\oerbin\pyvt\flask\lib\site-packages\werkzeug\local.py", line 378, in <lambda>
    __getitem__ = lambda x, i: x._get_current_object()[i]
  File "C:\Users\oerbin\pyvt\flask\lib\site-packages\flask\sessions.py", line 84, in __getitem__
    return super(SecureCookieSession, self).__getitem__(key)
KeyError: 'username'
2019-11-06 10:54:42,661 - ERROR - app.py - log_exception - 1891 - Exception on /login [GET]
Traceback (most recent call last):
  File "C:\Users\oerbin\pyvt\flask\lib\site-packages\flask\app.py", line 2446, in wsgi_app
    response = self.full_dispatch_request()
  File "C:\Users\oerbin\pyvt\flask\lib\site-packages\flask\app.py", line 1951, in full_dispatch_request
    rv = self.handle_user_exception(e)
  File "C:\Users\oerbin\pyvt\flask\lib\site-packages\flask\app.py", line 1820, in handle_user_exception
    reraise(exc_type, exc_value, tb)
  File "C:\Users\oerbin\pyvt\flask\lib\site-packages\flask\_compat.py", line 39, in reraise
    raise value
  File "C:\Users\oerbin\pyvt\flask\lib\site-packages\flask\app.py", line 1949, in full_dispatch_request
    rv = self.dispatch_request()
  File "C:\Users\oerbin\pyvt\flask\lib\site-packages\flask\app.py", line 1935, in dispatch_request
    return self.view_functions[rule.endpoint](**req.view_args)
  File "c:\Users\oerbin\python-code\monitor\main\views.py", line 32, in login
    if session['username']:
  File "C:\Users\oerbin\pyvt\flask\lib\site-packages\werkzeug\local.py", line 378, in <lambda>
    __getitem__ = lambda x, i: x._get_current_object()[i]
  File "C:\Users\oerbin\pyvt\flask\lib\site-packages\flask\sessions.py", line 84, in __getitem__
    return super(SecureCookieSession, self).__getitem__(key)
KeyError: 'username'
2019-11-06 10:54:46,204 - ERROR - app.py - log_exception - 1891 - Exception on /login [GET]
Traceback (most recent call last):
  File "C:\Users\oerbin\pyvt\flask\lib\site-packages\flask\app.py", line 2446, in wsgi_app
    response = self.full_dispatch_request()
  File "C:\Users\oerbin\pyvt\flask\lib\site-packages\flask\app.py", line 1951, in full_dispatch_request
    rv = self.handle_user_exception(e)
  File "C:\Users\oerbin\pyvt\flask\lib\site-packages\flask\app.py", line 1820, in handle_user_exception
    reraise(exc_type, exc_value, tb)
  File "C:\Users\oerbin\pyvt\flask\lib\site-packages\flask\_compat.py", line 39, in reraise
    raise value
  File "C:\Users\oerbin\pyvt\flask\lib\site-packages\flask\app.py", line 1949, in full_dispatch_request
    rv = self.dispatch_request()
  File "C:\Users\oerbin\pyvt\flask\lib\site-packages\flask\app.py", line 1935, in dispatch_request
    return self.view_functions[rule.endpoint](**req.view_args)
  File "c:\Users\oerbin\python-code\monitor\main\views.py", line 32, in login
    if session['username']:
  File "C:\Users\oerbin\pyvt\flask\lib\site-packages\werkzeug\local.py", line 378, in <lambda>
    __getitem__ = lambda x, i: x._get_current_object()[i]
  File "C:\Users\oerbin\pyvt\flask\lib\site-packages\flask\sessions.py", line 84, in __getitem__
    return super(SecureCookieSession, self).__getitem__(key)
KeyError: 'username'
